2024-12-22 17:21:42,013 INFO    MainThread:13068 [wandb_setup.py:_flush():68] Current SDK version is 0.19.1
2024-12-22 17:21:42,013 INFO    MainThread:13068 [wandb_setup.py:_flush():68] Configure stats pid to 13068
2024-12-22 17:21:42,013 INFO    MainThread:13068 [wandb_setup.py:_flush():68] Loading settings from C:\Users\aton\.config\wandb\settings
2024-12-22 17:21:42,013 INFO    MainThread:13068 [wandb_setup.py:_flush():68] Loading settings from C:\Users\aton\Downloads\Take Home Test\wandb\settings
2024-12-22 17:21:42,013 INFO    MainThread:13068 [wandb_setup.py:_flush():68] Loading settings from environment variables
2024-12-22 17:21:42,013 INFO    MainThread:13068 [wandb_init.py:_log_setup():528] Logging user logs to C:\Users\aton\Downloads\Take Home Test\wandb\run-20241222_172142-fbtvw2uq\logs\debug.log
2024-12-22 17:21:42,014 INFO    MainThread:13068 [wandb_init.py:_log_setup():529] Logging internal logs to C:\Users\aton\Downloads\Take Home Test\wandb\run-20241222_172142-fbtvw2uq\logs\debug-internal.log
2024-12-22 17:21:42,014 INFO    MainThread:13068 [wandb_init.py:init():644] calling init triggers
2024-12-22 17:21:42,014 INFO    MainThread:13068 [wandb_init.py:init():650] wandb.init called with sweep_config: {}
config: {}
2024-12-22 17:21:42,014 INFO    MainThread:13068 [wandb_init.py:init():680] starting backend
2024-12-22 17:21:42,014 INFO    MainThread:13068 [wandb_init.py:init():684] sending inform_init request
2024-12-22 17:21:42,040 INFO    MainThread:13068 [backend.py:_multiprocessing_setup():104] multiprocessing start_methods=spawn, using: spawn
2024-12-22 17:21:42,040 INFO    MainThread:13068 [wandb_init.py:init():697] backend started and connected
2024-12-22 17:21:42,042 INFO    MainThread:13068 [wandb_init.py:init():790] updated telemetry
2024-12-22 17:21:42,043 INFO    MainThread:13068 [wandb_init.py:init():822] communicating run to backend with 90.0 second timeout
2024-12-22 17:21:42,668 ERROR   MainThread:13068 [wandb_init.py:init():849] encountered error: failed to upsert bucket: returned error 403 Forbidden: {"errors":[{"message":"permission denied","path":["upsertBucket"],"extensions":{"code":"PERMISSION_ERROR"}}],"data":{"upsertBucket":null}}
2024-12-22 17:21:42,668 ERROR   MainThread:13068 [wandb_init.py:init():1308] error in wandb.init()
Traceback (most recent call last):
  File "C:\Users\aton\Downloads\Take Home Test\myenv\Lib\site-packages\wandb\sdk\wandb_init.py", line 1298, in init
    return wi.init()
           ^^^^^^^^^
  File "C:\Users\aton\Downloads\Take Home Test\myenv\Lib\site-packages\wandb\sdk\wandb_init.py", line 855, in init
    raise error
wandb.errors.errors.CommError: failed to upsert bucket: returned error 403 Forbidden: {"errors":[{"message":"permission denied","path":["upsertBucket"],"extensions":{"code":"PERMISSION_ERROR"}}],"data":{"upsertBucket":null}}
2024-12-22 17:21:42,679 WARNING MsgRouterThr:13068 [router.py:message_loop():75] message_loop has been closed
